Workbook

Sheet indice
A1: Capacitação em Direitos Humanos, Gênero, Raça e Etnia; e em Depoimento Especial" - 0148945-13.2024.8.16.6000 | B1: Capacitação de Facilitadores 0148959-94.2024.8.16.6000 | C1: Acessibilidade e Inclusão - 0148938-21.2024.8.16.6000 | D1: Política de Prevenção e Enfrentamento do Assédio Moral, do Assédio Sexual e da Discriminação.0148908-83.2024.8.16.6000 | E1: SUSTENTABILIDADE https://portal.tjpr.jus.br/portletforms/frm.do?idFormulario=7430 0017859-16.2024.8.16.6000
A2: cursos de formação inicial e de formação continuada para capacitação magistrados(as) ativos(as), de primeiro e segundo graus de jurisdição | B2: violência doméstica e familiar contra a mulher | C2: Acessibilidade comunicacional | D2: assédio moral | E2: equidade e diversidade
A3: direitos humanos, gênero, raça e etnia | C3: Acessibilidade tecnológica | D3: assédio sexual | E3: sustentabilidade
A4: depoimento especial | D4: discriminação | E4: elaborar inventários
E5: Emissões de GEE (gases de efeito estufa) e incentivos a práticas sustentáveis
B11: INDICADORES | C11: Tipo de evento | D11: MODALIDADE | E11: DECLARAÇÃO/ CERTIFICADO/ SEM CERTIFICAÇÃO | F11: ON LINE OU PRESENCIAL | G11: PUBLICO ALVO | H11: CATEGORIA DO Curso | I11: STATUS | J11: LIVRO DE REGISTRO
B12: ADMINISTRATIVO | C12: 1. CONGRESSO | D12: AUTOINSTRUCIONAL | E12: Certificado | F12: EAD | G12: LIVRE | H12: APOIO | I12: ARQUIVADO | J12: 1 - LISTA GERAL_2020 A ...
B13: ADOÇÃO | C13: 2. SIMPÓSIO | D13: EVENTO EXTERNO | E13: Declaração | F13: HÍBRIDO (presencial e EAD) | G13: MAGISTRADOS | H13: CONTRATAÇÃO | I13: CURSO FECHADO | J13: 2 - IN COMPANY
B14: BRIGADISTA | C14: 3. SEMINÁRIO | D14: IN COMPANY | E14: Sem certificação | F14: PRESENCIAL | G14: PÚBLICO EXTERNO | H14: CONVITE | I14: PRONTO PARA REGISTRO | J14: 3 - CONCILIAJUD
B15: DTOS HUMANOS E CIDADANIA | C15: 4. PAINEL ACADÊMICO | D15: REPOSITÓRIO | F15: PRESENCIAL COM TRANSMISSÃO AO VIVO | G15: QUADRO INTERNO | H15: DIVULGAÇÃO | I15: NÃO REALIZADO | J15: 3 - EVENTO EXTERNO
B16: ECA | C16: 5. FÓRUM | D16: CERTIFICAÇÃO | F16: TRANSMISSÃO AO VIVO | G16: RESTRITOS | H16: ELABORAÇÃO | I16: SOBRESTADO
B17: GESTÃO | C17: 6. COLÓQUIO | D17: DIVULGAÇÃO | F17: WEBCONFERÊNCIA (teams/zoom) | G17: SERVIDORES | H17: REPLICAÇÃO | I17: SUSPENSO
B18: INOVAÇÃO | C18: 7. CONFERÊNCIA | I18: AUTORIZADO
B19: MEDIAÇÃO | C19: 8. MESA REDONDA
B20: RISCO E COMPLIENCE | C20: 9. JORNADA ACADÊMICA
B21: SAÚDE | C21: 10. SEMANA ACADÊMICA
B22: TECNOLOGIA | C22: 11. WORKSHOP
C23: 12. CURSOS
C24: 13. LIVES
C25: Magistrados - Cred. Enfam
C26: Magistrados - Não Cred
B27: JUSTIÇA RESTAURATIVA
B28: MAGISTRADO
B29: MEIO AMBIENTE
B30: SUSTENTABILIDADE
B31: DEPOIMENTO ESPECIAL
B32: assédio moral, sexual e discriminação.
B33: ACESSIBILIDADE E INCLUSÃO
B34: VIOLÊNCIA DOMESTICA
B35: Reflexão e sensibilização de autores de violência doméstica e familiar

Sheet Cursos antigos
B1: ANO DO CURSO2 | C1: BLOCO | D1: SEI | E1: NOME DO Curso | F1: CATEGORIA DO Curso | G1: RESPONSÁVEL PELA CERTIFICAÇÃO | H1: INSTITUIÇÃO DE ENSINO | I1: EMPRESA CONTRATADA | J1: CNPJ | K1: SEI DOC INSTRUTORES | L1: Intrutor (andamento do SEI) | M1: TERMO DE USO DE IMAGEM | N1: ATESTO | O1: PRE ANOTAÇÃO ATESTO | P1: REG DE INSTRUTORES | Q1: DESPESAS | R1: VALOR DAS DESPESAS | S1: PRODUÇÃO/UNIDADE SOLICITANTE | T1: Eixo de Capacitação - Itinerários Formativos | U1: PAE | V1: INDICADORES | W1: PORTARIA ENFAM | X1: Tipo de evento | Y1: TURMA | Z1: nº de vagas | AA1: INTÉRPRETES DE LIBRAS | AB1: MODALIDADE | AC1: PLANO DE CURSO/SEI | AD1: LOCAL | AE1: ANO DO CURSO2 | AF1: DATA INÍCIO | AG1: DATA TERMINO | AH1: DECLARAÇÃO/ CERTIFICADO/ SEM CERTIFICAÇÃO | AI1: ON LINE OU PRESENCIAL | AJ1: PUBLICO ALVO | AK1: RELATORIO_CARGA HORÁRIA | AL1: CARGA HORARIA | AM1: ID | AN1: LINK AVA/ANDAMENTO DO CERTIFICADO | AO1: lista de presença | AP1: SEI DOS INSCRITOS | AQ1: STATUS | AR1: pronto para registro | AS1: DATA DA ULTIMA VERIFICAÇÃO | AT1: obs 2: | AU1: LIVRO DE REGISTRO | AV1: DATA DO ULTIMO REGISTRO | AW1: 2021 | AX1: 2022 | AY1: 1º trim/2023 | AZ1: 2º trim/2023 | BA1: 3º trim/2023 | BB1: 4º trim/2023 | BC1: 2023 | BD1: TOTAL CERTIFICADOS EMITIDOS/2024 | BE1: 1º trim/2024 | BF1: 2º trim/2024 | BG1: 3º trim/2024 | BH1: 4º trim/2024 | BI1: TOTAL CERTIFICADOS EMITIDOS/2025 | BJ1: 1º trim/2025 | BK1: 2º trim/2025 | BL1: 3º trim/2025 | BM1: 4º trim/2025
B2: 0 | E2: Escola Judicial do Paraná | Tribunal de Justiça do Paraná | AD2: Paraná | AM2: 1 | AQ2: Curso fechado
B3: 0 | E3: Mediação Judicial _ padrão | V3: MEDIAÇÃO | AM3: 2 | AQ3: Curso fechado
B4: 0 | E4: Instrutor EAD em mediação judicial | V4: MEDIAÇÃO | AM4: 4 | AQ4: Curso fechado
B5: 0 | E5: Mediação Judicial - turma 1 | V5: MEDIAÇÃO | Y5: turma 1 | AM5: 5 | AQ5: Curso fechado
B6: 0 | E6: Mediação Judicial - turma 2 | V6: MEDIAÇÃO | Y6: turma 2 | AM6: 6 | AQ6: Curso fechado
B7: 0 | E7: Mediação Judicial - turma 3 | V7: MEDIAÇÃO | Y7: turma 3 | AM7: 7 | AQ7: Curso fechado
B8: 0 | E8: Mediação Judicial - turma 4 | V8: MEDIAÇÃO | Y8: turma 4 | AM8: 8 | AQ8: Curso fechado
B9: 0 | E9: Mediação Judicial - turma 5 | V9: MEDIAÇÃO | Y9: turma 5 | AM9: 9 | AQ9: Curso fechado
B10: 0 | E10: Mediação Judicial - turma 6 | V10: MEDIAÇÃO | Y10: turma 6 | AM10: 10 | AQ10: Curso fechado
B11: 0 | E11: Mediação Judicial - teste | V11: MEDIAÇÃO | AM11: 11 | AQ11: Curso fechado
B12: 0 | E12: Mediação Judicial - Turma Recuperação | V12: MEDIAÇÃO | Y12: Turma Recuperação | AM12: 12 | AQ12: Curso fechado
B13: 0 | E13: Mediação Judicial_002/2014 | V13: MEDIAÇÃO | Y13: Judicial_002/2014 | AM13: 13 | AQ13: Curso fechado
B14: 0 | E14: Mediação Judicial 003/2014 | V14: MEDIAÇÃO | Y14: Judicial 003/2014 | AM14: 14 | AQ14: Curso fechado
B15: 0 | E15: Palestras Públicas | AM15: 15 | AQ15: Curso fechado
B16: 0 | E16: Instrutores em mediação e conciliação | V16: MEDIAÇÃO | AM16: 16 | AQ16: Curso fechado
B17: 0 | E17: Mediação para representantes de empresas | V17: MEDIAÇÃO | AM17: 17 | AQ17: Curso fechado
B18: 0 | E18: Relações Interpessoais e Administração de Conflitos | AM18: 18 | AQ18: Curso fechado
B19: 0 | E19: Mediação Judicial 004/2014 | V19: MEDIAÇÃO | Y19: Judicial 004/2014 | AM19: 21 | AQ19: Curso fechado
B20: 0 | E20: Mediação Judicial - presencial - Ponta Grossa | V20: MEDIAÇÃO | AD20: Ponta Grossa | AM20: 22 | AQ20: Curso fechado
B21: 0 | E21: Mediação Judicial 005/2014 | V21: MEDIAÇÃO | Y21: Judicial 005/2014 | AM21: 25 | AQ21: Curso fechado
B22: 0 | E22: Educação Ambiental e Sustentabilidade | AD22: Sustentabilidade | AM22: 26 | AQ22: Curso fechado
B23: 0 | E23: Desenvolvimento de Competências Gerenciais | AD23: Gerenciais | AM23: 30 | AQ23: Curso fechado
B24: 2015 | E24: Oficial de Justiça - 2015 | AE24: 2015 | AM24: 31 | AQ24: Curso fechado
B25: 0 | E25: Noções Básicas de Administração | AM25: 33 | AQ25: Curso fechado
B26: 0 | E26: Fundamentos de Ensino a Distância | AM26: 34 | AQ26: Curso fechado
B27: 0 | E27: Introdução à Capacitação Gerencial Turma I - Zona 21 a 57 | AM27: 35 | AQ27: Curso fechado
B28: 0 | E28: Atendimento ao público para CNJ | AM28: 36 | AQ28: Curso fechado
B29: 0 | E29: Atualização em Gramática da Língua Portuguesa turma teste | AM29: 37 | AQ29: Curso fechado
B30: 0 | E30: Introdução ao Orçamento Público | AM30: 38 | AQ30: Curso fechado
B31: 0 | E31: Noções Básicas de Administração | AM31: 39 | AQ31: Curso fechado
B32: 0 | E32: Tutoria no Ensino a Distância | AM32: 40 | AQ32: Curso fechado
B33: 0 | E33: Introdução à Lei de Responsabilidade Fiscal | AM33: 41 | AQ33: Curso fechado
B34: 0 | E34: Licitações e Contratos | AM34: 42 | AQ34: Curso fechado
B35: 0 | E35: Formação de Tutores para o curso Desenvolvimento de Competências Gerenciais | AM35: 43 | AQ35: Curso fechado
B36: 0 | E36: Administração Judiciária | AM36: 44 | AQ36: Curso fechado
B37: 0 | E37: Curso de Mediação Judicial | V37: MEDIAÇÃO | AM37: 51 | AQ37: Curso fechado
B38: 0 | E38: Curso de Mediação Judicial NUPEMEC/CNJ/2016 | V38: MEDIAÇÃO | AM38: 53 | AQ38: Curso fechado
B39: 0 | E39: Depoimento Especial e a Escuta de Crianças no Sistema de Justiça | V39: Depoimento Especial | AM39: 56 | AQ39: Curso fechado
B40: 2016 | D40: 0028066-55.2016.8.16.6000 | E40: Protesto das Custas Processuais | V40: - | AM40: 57 | AQ40: Curso fechado
...

Sheet controle de cursos
A1: CNJ - Capacitação em Direitos Humanos, Gênero, Raça e Etnia; e em Depoimento Especial" - 0148945-13.2024.8.16.6000 | B1: Prêmio CNJ de Qualidade - 2025 - Justiça Restaurativa - 0148919-15.2024.8.16.6000 | C1: Prêmio CNJ de Qualidade - 2025 - Capacitação de Facilitadores 0148959-94.2024.8.16.6000 | D1: Prêmio CNJ de Qualidade - 2025 - Acessibilidade e Inclusão - 0148938-21.2024.8.16.6000 | E1: Prêmio CNJ de Qualidade - 2025 Política de Prevenção e Enfrentamento do Assédio Moral, do Assédio Sexual e da Discriminação.0148908-83.2024.8.16.6000 | F1: sustentabilidade https://portal.tjpr.jus.br/portletforms/frm.do?idFormulario=7430 | G1: Coluna2 | H1: ANO DO CURSO2 | I1: SEI | J1: NOME DO Curso | K1: CATEGORIA DO Curso=modalidade | L1: RESPONSÁVEL PELA CERTIFICAÇÃO | M1: INSTITUIÇÃO DE ENSINO | N1: EMPRESA CONTRATADA | O1: CNPJ | P1: SEI DOC INSTRUTORES | Q1: Intrutor (andamento do SEI) | R1: TERMO DE USO DE IMAGEM | S1: ATESTO | T1: PRE ANOTAÇÃO ATESTO | U1: DESPESAS | V1: VALOR DAS DESPESAS | W1: PRODUÇÃO/UNIDADE SOLICITANTE | X1: Eixo de Capacitação - Itinerários Formativos | Y1: PAE | Z1: INDICADORES | AA1: PORTARIA ENFAM | AB1: Tipo de evento | AC1: TURMA | AD1: nº de vagas | AE1: INTÉRPRETES DE LIBRAS | AF1: MODALIDADE | AG1: PLANO DE CURSO/SEI | AH1: LOCAL | AI1: ANO DO CURSO22 | AJ1: DATA INÍCIO | AK1: DATA TERMINO | AL1: DECLARAÇÃO/ CERTIFICADO/ SEM CERTIFICAÇÃO | AM1: ON LINE OU PRESENCIAL | AN1: PUBLICO ALVO | AO1: RELATORIO_CARGA HORÁRIA | AP1: CARGA HORARIA | AQ1: ID | AR1: LINK AVA/ANDAMENTO DO CERTIFICADO | AS1: lista de presença | AT1: SEI DOS INSCRITOS | AU1: STATUS | AV1: pronto para registro | AW1: DATA DA ULTIMA VERIFICAÇÃO | AX1: obs 2: | AY1: REG DE INSTRUTORES | AZ1: REGISTRO DE INSTRUTORES NO SEI | BA1: LIVRO DE REGISTRO | BB1: REGISTRO NO SEI | BC1: DATA DO ULTIMO REGISTRO | BD1: REGISTRO NO SEI/2021 | BE1: TOTAL CERTIFICADOS EMITIDOS/2021 | BF1: REGISTRO NO SEI/20222 | BG1: TOTAL CERTIFICADOS EMITIDOS/2022 | BH1: REGISTRO NO SEI/2023 | BI1: TOTAL CERTIFICADOS EMITIDOS/2023 | BJ1: 1º trim/2023 | BK1: 2º trim/2023 | BL1: 3º trim/2023 | BM1: 4º trim/2023 | BN1: REGISTRO NO SEI/2024 | BO1: TOTAL CERTIFICADOS EMITIDOS/2024 | BP1: 1º trim/2024 | BQ1: 2º trim/2024 | BR1: 3º trim/2024 | BS1: 4º trim/2024 | BT1: REGISTRO NO SEI/2025 | BU1: TOTAL CERTIFICADOS EMITIDOS/2025 | BV1: 1º trim/2025 | BW1: 2º trim/2025 | BX1: 3º trim/2025 | BY1: 4º trim/2025
H2: 2021 | I2: 0051257-56.2021.8.16.6000 | J2: 1ª Oficina de Ideação da Magistratura Paranaense | VALORIZAÇÃO Valorização - Jornada de Valorização da Magistratura Paranaense | AB2: Oficina | AI2: 2021 | AJ2: 44355 | AK2: 44388 | AL2: Certificado | AN2: MAGISTRATURA | AQ2: 675 | AR2: https://ead.tjpr.jus.br/course/view.php?id=675 | AU2: Curso fechado | AX2: registrado_65 pessoas_sem informar o sei
H3: 2022 | I3: 0060212-42.2022.8.16.6000 | J3: Curso de Justiça Restaurativa: Formação Prática I - Processos Circulares não Conflitivos | W3: NUPEMEC | Z3: JUSTIÇA RESTAURATIVA | AB3: Curso | AC3: 1 Ed | AD3: 20 | AI3: 2022 | AJ3: 44714 | AK3: 44742 | AQ3: 702 | AR3: https://ead.tjpr.jus.br/course/view.php?id=702 | AU3: Curso fechado | BC3: 44791 | BG3: 2022 | BI3: #VALUE!
B4: sim | H4: 2022 | I4: 0060247-02.2022.8.16.6000 | J4: Curso Formação Prática I em Justiça Restaurativa - JR - 2022 - 2ª Edição - Turma 2 | W4: NUPEMEC | Z4: JUSTIÇA RESTAURATIVA | AB4: Curso | AC4: 2 ed | AD4: 20 | AI4: 2022 | AJ4: 44718 | AK4: 44748 | AQ4: 736 | AR4: https://ead.tjpr.jus.br/course/view.php?id=736 | AU4: Curso fechado | BG4: 2022 | BI4: #VALUE!
B5: sim | H5: 2022 | I5: 0060391-73.2022.8.16.6000 | J5: Curso Formação Prática I em Justiça Restaurativa - JR - 2022 - 4ª Edição - Turma 4 - Ponta Grossa - 2022 | W5: NUPEMEC | Z5: JUSTIÇA RESTAURATIVA | AB5: Curso | AC5: 4 ED | AI5: 2022 | AJ5: 44730 | AK5: 44750 | AQ5: 755 | AR5: https://ead.tjpr.jus.br/course/view.php?id=755 | AU5: Curso fechado | BG5: 2022 | BI5: #VALUE!
B6: sim | H6: 2022 | I6: 0060331-03.2022.8.16.6000 | J6: Curso Formação Prática I em Justiça Restaurativa - JR - 2022 - 3ª Edição - Turma 3 | W6: NUPEMEC | Z6: JUSTIÇA RESTAURATIVA | AB6: Curso | AC6: 3 ED | AD6: 20 | AI6: 2022 | AJ6: 44733 | AK6: 44757 | AQ6: 738 | AR6: https://ead.tjpr.jus.br/course/view.php?id=738 | AU6: Curso fechado | BG6: 2022 | BI6: #VALUE!
H7: 2022 | I7: 0072539-19.2022.8.16.6000 | J7: III Semana de Integração e Aperfeiçoamento | AG7: Projeto Semana de Integração e Aperfeiçoamento – Jul./2022 (7784471) | AI7: 2022 | AJ7: 44743 | AK7: 44750 | AR7: https://ead.tjpr.jus.br/course/view.php?id=1033 | AU7: Curso fechado | AX7: autorizada a emissáo do certificado | BC7: 45600 | BQ7: 29
B8: sim | H8: 2022 | I8: 0060474-89.2022.8.16.6000 | J8: Curso Formação Prática I em Justiça Restaurativa - JR - 2022 - 5ª Edição - Turma 5 - presencial Toledo | W8: NUPEMEC | Z8: JUSTIÇA RESTAURATIVA | AB8: Curso | AC8: 5 ED | AI8: 2022 | AJ8: 44768 | AK8: 44771 | AQ8: 756 | AR8: https://ead.tjpr.jus.br/course/view.php?id=756 | AU8: Curso fechado | BG8: ? | BI8: #VALUE!
B9: sim | H9: 2022 | I9: 0130331-28.2022.8.16.6000 | J9: Curso de Justiça Restaurativa: Formação Prática I - Processos Circulares não Conflitivos - 6ª Edição | W9: NUPEMEC | Z9: JUSTIÇA RESTAURATIVA | AB9: Curso | AI9: 2022 | AJ9: 44866 | AK9: 44910 | AQ9: 796 | AR9: https://ead.tjpr.jus.br/course/view.php?id=796 | AU9: curso fechado | BC9: 44959 | BI9: #VALUE! | BJ9: 17 | BO9: 17
B10: sim | H10: 2022 | I10: 0130369-40.2022.8.16.6000 | J10: Curso de Justiça Restaurativa - Formação Prática I - 7ª Edição | W10: NUPEMEC | Z10: JUSTIÇA RESTAURATIVA | AB10: Curso | AI10: 2022 | AJ10: 44868 | AK10: 44896 | AQ10: 797 | AR10: https://ead.tjpr.jus.br/course/view.php?id=797 | AU10: Curso fechado | BC10: 44959 | BI10: #VALUE! | BJ10: 16 | BO10: 16
B11: sim | H11: 2023 | I11: 0130372-92.2022.8.16.6000. | J11: 8a Edição do Curso de Justiça Restaurativa - Formação Prática I (Círculos não conflitivos) | L11: EJUD | W11: NUPEMEC | Z11: JUSTIÇA RESTAURATIVA | AB11: Curso | AI11: 2023 | AJ11: 45005 | AK11: 45028 | AQ11: 798 | AR11: https://ead.tjpr.jus.br/course/view.php?id=798 | AU11: Curso fechado | AY11: sim em 2024 | BA11: 1 - LISTA GERAL_2020 A ... | BC11: 45049 | BI11: #VALUE! | BJ11: 19 | BO11: 19
H12: 2023 | I12: 0049503-11.2023.8.16.6000 | J12: CURSO OFICIAL DE FORMAÇÃO INICIAL PARA JUIZ SUBSTITUTO | L12: EJUD | W12: EJUD | AA12: 088/2022 | AB12: curso | AD12: 20 | AH12: Curitiba | AI12: 2023 | AJ12: 45048 | AK12: 45134 | AL12: Certificado | AM12: presencial | AN12: MAGISTRATURA | AO12: 20 | AP12: 480 h | AQ12: 843 | AR12: https://ead.tjpr.jus.br/course/view.php?id=843 | AU12: Curso fechado | AX12: registrado alguns instrutores - certificado 2023 | AY12: 470-548/2023 | BA12: 1 - LISTA GERAL_2020 A ... | BC12: 45174 | BI12: #VALUE! | BL12: 15
H13: 2023 | I13: 0058337-03.2023.8.16.6000 | J13: CURSOS DE FORMAÇÃO DE CONCILIADORES E MEDIADORES JUDICIAL | Z13: MEDIAÇÃO | AH13: Maringá | AI13: 2023 | AJ13: 45062 | AK13: 45083 | AL13: Declaração | AM13: presencial | AP13: 40 h | AU13: curso fechado | BC13: 45672 | BO13: 11
E14: sim | H14: 2023 | I14: 0050268-79.2023.8.16.6000 | J14: Entre o ideal e o Possível: a importância da rede na aplicação das medidas de proteção (dia 24/05/2023 | Q14: 9035156 | X14: Formação Inicial e Continuada | AA14: não | AB14: Palestra | AH14: Paraná | AI14: 2023 | AJ14: 45070 | AK14: 45070 | AL14: Certificado | AM14: webconferência | AO14: 0.33333333 | AP14: 8 h | AQ14: 860 | AR14: https://ead.tjpr.jus.br/course/view.php?id=860 | AU14: Curso fechado | BA14: 1 - LISTA GERAL_2020 A ... | BC14: 45146 | BI14: #VALUE! | BK14: 82
E15: sim | H15: 2023 | I15: 0050268-79.2023.8.16.6000 | J15: Entre o ideal e o Possível: a importância da rede na aplicação das medidas de proteção (dia 25/05/2023 | Q15: 9035156 | X15: Formação Inicial e Continuada | AA15: não | AB15: Palestra | AH15: Paraná | AI15: 2023 | AJ15: 45071 | AK15: 45071 | AL15: Certificado | AM15: webconferência | AO15: 0.20833333 | AP15: 5 h | AQ15: 860 | AR15: https://ead.tjpr.jus.br/course/view.php?id=860 | AU15: Curso fechado | BA15: 1 - LISTA GERAL_2020 A ... | BC15: 45146 | BI15: #VALUE! | BK15: 83
F16: sim | H16: 2023 | I16: 0070561-70.2023.8.16.6000 | J16: 5º Ciclo de Treinamento e Reciclagem | L16: EJUD | Q16: 9137444 | W16: DGP-Departamento de Gestão de Precatórios | X16: Formação Inicial e Continuada | AA16: não | AD16: 70 | AH16: Curitiba | AI16: 2023 | AJ16: 45075 | AK16: 45091 | AM16: presencial | AN16: servidores(as) e estagiários(as) | AO16: 0.33333333 | AP16: 8 h | AQ16: 857 | AR16: https://ead.tjpr.jus.br/course/view.php?id=857 | AU16: Curso fechado | AY16: 419-426 | BA16: 1 - LISTA GERAL_2020 A ... | BC16: 45146 | BI16: #VALUE! | BL16: 60
E17: sim | H17: 2023 | I17: 0052563-89.2023.8.16.6000 | J17: II Fórum Paranaense de Violência Doméstica e Familiar contra a Mulher (FOVID/PR) | Q17: 9018411 | W17: CEVID | AA17: não | AB17: Fórum | AD17: 280 | AH17: Paraná | AI17: 2023 | AJ17: 45077 | AK17: 45079 | AL17: Certificado | AM17: webconferência | AO17: 0.95833333 | AP17: 23 h | AQ17: 858 | AR17: https://ead.tjpr.jus.br/course/view.php?id=858 | AU17: Curso fechado | AX17: 15/08 - ag. lista de presença no ava - 20/09juntada da lista de presença | AY17: 459-469 | BA17: 1 - LISTA GERAL_2020 A ... | BC17: 45404 | BI17: #VALUE! | BK17: 400 | BP17: 3
H18: 2023 | I18: 0054248-34.2023.8.16.6000 | J18: Instruções BNMP | Q18: 9094414 | W18: CGJ | Z18: Gestão | AB18: Curso | AH18: Paraná | AI18: 2023 | AJ18: 45082 | AK18: 45082 | AL18: certificado | AM18: transmissão ao vivo | AN18: magistrados(as) e servidores(as) da esfera criminal do TJPR | AO18: 0.16666667 | AP18: 4 h | AQ18: 863 | AR18: https://ead.tjpr.jus.br/course/view.php?id=863 | AU18: Curso fechado | AY18: 417-418 | BA18: 1 - LISTA GERAL_2020 A ... | BC18: 45146 | BI18: #VALUE! | BL18: 758
A19: sim | H19: 2023 | I19: 0049473-73.2023.8.16.6000 | J19: Seminário Internacional de Saúde Mental: Possibilidades para a efetivação da Política Antimanicomial na interface com o Poder Judiciário | Q19: espalhado | W19: CNJ | AA19: não | AB19: Seminário | AD19: 400 | AH19: Curitiba | AI19: 2023 | AJ19: 45092 | AK19: 45093 | AL19: Certificado | AM19: presencial com transmissão ao vivo | AO19: 0.70833333 | AP19: 17 h | AQ19: 862 | AR19: https://ead.tjpr.jus.br/course/view.php?id=862 | AU19: Curso fechado | AY19: 430-444/803-814/2024 | BA19: 1 - LISTA GERAL_2020 A ... | BC19: 45153 | BI19: #VALUE! | BK19: 586
H20: 2023 | I20: 0062706-40.2023.8.16.6000 | J20: Curso de Aperfeiçoamento para Magistrados e Magistradas – Medidas Protetivas de Urgência no Âmbito da Lei 11340/2006. Fundamentos, questões controvertidas e efetividade | Q20: 9086742 | AA20: 126/2023 | AB20: Curso | AD20: 80 | AI20: 2023 | AJ20: 45092 | AK20: 45131 | AL20: certificado | AM20: transmissão ao vivo | AN20: MAGISTRATURA | AO20: 0.83333333 | AP20: 20 h | AQ20: 859 | AR20: https://ead.tjpr.jus.br/course/view.php?id=859 | AU20: Curso fechado | AY20: 448-452 | BA20: 1 - LISTA GERAL_2020 A ... | BC20: 45155 | BI20: #VALUE! | BL20: 68
F21: sim | H21: 2023 | I21: 0070644-86.2023.8.16.6000 | J21: curso “Sustentabilidade Ambiental e Populações Tradicionais: direito ao Meio Ambiente Ecologicamente Equilibrado” | L21: EJUD | Q21: José Ricardo Alvarez Vianna | W21: EJUD | AA21: 039/2023 | AB21: curso | AD21: 40 | AH21: Paraná | AI21: 2023 | AJ21: 45099 | AK21: 45131 | AL21: Certificado | AM21: EAD | AN21: MAGISTRATURA | AO21: 1.25 | AP21: 30 h | AQ21: 846 | AR21: https://ead.tjpr.jus.br/course/view.php?id=846 | AU21: Curso fechado | AY21: 470 | BA21: 1 - LISTA GERAL_2020 A ... | BC21: 45160 | BI21: #VALUE! | BL21: 20
A22: sim | E22: sim | H22: 2023 | I22: 0078947-89.2023.8.16.6000 | J22: O Protocolo para Julgamento com a Perspectiva de Gênero - Edição 2024 | Z22: MAGISTRADO | AG22: Plano de curso (9174100) | AI22: 2023 | AJ22: 45101 | AK22: 45131 | AN22: MAGISTRADO | AQ22: 999 | AU22: Curso fechado | BC22: 45520 | BQ22: 33
A23: sim | E23: sim | H23: 2023 | I23: 0078947-89.2023.8.16.6000 | J23: Protocolo para julgamento com perspectiva de gênero - 3ed | L23: EJUD | Q23: 9176202 | AA23: 157/2022 | AB23: Curso | AD23: 40 | AI23: 2023 | AJ23: 45101 | AK23: 45131 | AL23: Certificado | AM23: transmissão ao vivo | AN23: MAGISTRATURA | AO23: 1.0833333 | AP23: 26 h | AQ23: 861 | AR23: https://ead.tjpr.jus.br/course/view.php?id=861 | AU23: Curso fechado | AY23: 445/446 | BA23: 1 - LISTA GERAL_2020 A ... | BC23: 45154 | BI23: #VALUE! | BL23: 33
H24: 2023 | I24: 0078648-15.2023.8.16.6000 | J24: Cooperação Judiciária e o CPC/15: Perspectivas e Desafios | L24: EJUD | Q24: 9309073 | W24: Núcleo de Cooperação Judiciária | X24: Formação Inicial e Continuada | AA24: não | AB24: Live | AH24: Paraná | AI24: 2023 | AJ24: 45132 | AK24: 45132 | AM24: transmissão ao vivo | AN24: MAGISTRATURA | AO24: 0.083333333 | AP24: 2 h | AQ24: 874 | AR24: https://ead.tjpr.jus.br/course/view.php?id=874 | AU24: Curso fechado | AY24: 427-429 | BA24: 1 - LISTA GERAL_2020 A ... | BC24: 45146 | BI24: #VALUE! | BL24: 128
H25: 2023 | I25: 0059165-67.2021.8.16.6000 | J25: Adequação da numeração única dos Recursos no Projudi | W25: DPLAN-DE - Divisão de Estatística do Departamento de Planejamento | AA25: não | AB25: live | AI25: 2023 | AJ25: 45135 | AK25: 45135 | AL25: Certificado | AM25: transmissão ao vivo | AN25: Livre | AO25: 0.055555556 | AP25: 1h 20min | AQ25: 875 | AR25: https://ead.tjpr.jus.br/course/view.php?id=875 | AU25: Curso fechado | AY25: 453-458 | BA25: 1 - LISTA GERAL_2020 A ... | BC25: 45160 | BI25: #VALUE! | BL25: 104
E26: sim | H26: 2023 | I26: 0013489-28.2023.8.16.6000 | J26: Curso de violência doméstica e familiar contra a mulher para Magistrados(as) | Q26: 9556723 | Z26: violencia domestica | AA26: 074/2023 | AB26: Curso | AD26: 80 | AH26: Paraná | AI26: 2023 | AJ26: 45141 | AK26: 45180 | AL26: Certificado | AM26: EAD | AN26: MAGISTRATURA | AO26: 1.6666667 | AP26: 40 h | AQ26: 869 | AR26: https://ead.tjpr.jus.br/course/view.php?id=869 | AU26: Curso fechado | AX26: 18/10- forcei a certificação | AY26: 599-602/2023 | BA26: 1 - LISTA GERAL_2020 A ... | BC26: 45217 | BI26: #VALUE! | BL26: 48
H27: 2023 | I27: 0058310-20.2023.8.16.6000 | J27: Programa de Consultoria sobre o Sistema de Controle Interno do Poder Judiciário | W27: DAUDI-D - Diretoria do Departamento de Auditoria Interna | AB27: Curso | AI27: 2023 | AJ27: 45141 | AK27: 45147 | AL27: Certificado | AM27: presencial | AO27: 0.125 | AP27: 3 h | AQ27: 876 | AR27: https://ead.tjpr.jus.br/course/view.php?id=876 | AU27: Curso fechado | AX27: 26/09 - forcei a expedição dos certificados | AY27: 588-590/2023 | BA27: 1 - LISTA GERAL_2020 A ... | BC27: 45195 | BI27: #VALUE! | BL27: 128
B28: sim | H28: 2023 | I28: 0079751-57.2023.8.16.6000 | J28: Curso Formação de Formadores - Desenvolvimento Docente N1M1 | L28: EJUD | Q28: 9180806 | AA28: 302/2021 | AB28: curso | AC28: 2 ED | AD28: 40 | AH28: Paraná | AI28: 2023 | AJ28: 45141 | AK28: 45166 | AL28: Certificado | AM28: EAD | AN28: MAGISTRATURA | AO28: 1.0833333 | AP28: 26h | AQ28: 865 | AR28: https://ead.tjpr.jus.br/course/view.php?id=865 | AU28: Curso fechado | AY28: 576 -580/2023_expedido em 16/02/2024 | BA28: 1 - LISTA GERAL_2020 A ... | BC28: 45181 | BI28: #VALUE! | BL28: 37
H29: 2023 | I29: 0073414-52.2023.8.16.6000 | J29: Curso de Justiça Restaurativa: Formação Prática I - Processos Circulares não Conflitivos 9ª Edição | L29: EJUD | AD29: 20 | AH29: Paraná | AI29: 2023 | AJ29: 45145 | AK29: 45168 | AL29: Declaração | AM29: webconferência | AO29: 1.6666667 | AP29: 40 h | AQ29: 872 | AR29: https://ead.tjpr.jus.br/course/view.php?id=872 | AU29: Curso fechado | AX29: 25/09 - declaração no ava | AY29: 591-592/2023 | BA29: 1 - LISTA GERAL_2020 A ... | BC29: 45195 | BI29: #VALUE! | BL29: 20 | BO29: 20
H30: 2023 | I30: 0098485-56.2023.8.16.6000 | J30: V Semana de Integração e Aperfeiçoamento | L30: EJUD | W30: Unidade Especial de Atuação no Primeiro Grau de Jurisdição (UEA) | AH30: Paraná | AI30: 2023 | AJ30: 45145 | AK30: 45149 | AM30: webconferência | AN30: Servidores e estagiários da UEA | AO30: 0.45833333 | AP30: 11 h | AQ30: 877 | AR30: https://ead.tjpr.jus.br/course/view.php?id=877 | AU30: Curso fechado | BA30: 1 - LISTA GERAL_2020 A ... | BC30: 45168 | BI30: #VALUE! | BL30: 25
H31: 2023 | I31: 0099050-20.2023.8.16.6000 | J31: Nova Lei de Licitações com ênfase na prática do sistema COMPRAS.GOV | L31: EJUD | W31: DP-DL - Divisão de Licitações do Departamento do Patrimônio | AB31: CURSO | AC31: 1 | AD31: 40 | AF31: IN COMPANY | AI31: 2023 | AJ31: 45145 | AK31: 45148 | AL31: CERTIFICADO | AN31: Compradores, Pregoeiros e membros de Equipes de Apoio, assessores jurídicos, agentes de controle interno, além de servidores e profissionais atuantes no cenário das compras públicas em geral | AO31: 0.66666667 | AP31: 16 h | AU31: Curso fechado | BA31: IN COMPANY | BC31: 45166 | BI31: #VALUE! | BL31: 41
B32: sim | H32: 2023 | I32: 0078697-56.2023.8.16.6000 | J32: 10ª Edição do Curso Formação Prática I em Justiça Restaurativa. | L32: EJUD | W32: NUPEMEC | Z32: JUSTIÇA RESTAURATIVA | AB32: Curso | AC32: 10 Edição | AD32: 20 | AH32: Paraná | AI32: 2023 | AJ32: 45147 | AK32: 45170 | AL32: Declaração | AM32: EAD | AO32: 1.6666667 | AP32: 40 h | AQ32: 873 | AR32: https://ead.tjpr.jus.br/course/view.php?id=873 | AU32: Curso fechado | AY32: 593-594/2023 | BA32: 1 - LISTA GERAL_2020 A ... | BC32: 45195 | BI32: #VALUE! | BL32: 18 | BO32: 18
F33: sim | H33: 2023 | I33: 0083639-34.2023.8.16.6000 | J33: Webinar de Sustentabilidade - 2 live | L33: EJUD | Q33: 9275525 | W33: GCJ-GJACJ-AC - Assessoria Correicional do Gabinete dos Juizes Auxiliares do Corregedor-geral da Justiça | X33: Formação Inicial e Continuada | Z33: Sustentabilidade | AA33: não | AB33: live | AI33: 2023 | AJ33: 45147 | AK33: 45147 | AL33: Certificado | AM33: transmissão ao vivo | AN33: Livre | AO33: 0.041666667 | AP33: 1 h | AQ33: 870 | AR33: https://ead.tjpr.jus.br/course/view.php?id=870 | AU33: Curso fechado | AY33: 447 | BA33: 1 - LISTA GERAL_2020 A ... | BC33: 45154 | BI33: #VALUE! | BL33: 140
H34: 2023 | I34: 0078413-48.2023.8.16.6000 | J34: O testamento vital como instrumento para autodeterminação no fim de vida | L34: EJUD | Q34: Luciana Dadalto | W34: CPER-CPASMS - Comissão Permanente de Apoio à Saúde dos Magistrados e Servidores das Comissões Permanentes | X34: Formação Inicial e Continuada | AA34: não | AB34: live | AI34: 2023 | AJ34: 45149 | AK34: 45149 | AL34: SEM CERTIFICAÇÃO | AM34: transmissão ao vivo | AN34: Livre | AO34: 0.041666667 | AP34: 1 h | AR34: não | AU34: Curso fechado | AX34: sem certificação - 9270321 | BI34: #VALUE!
H35: 2023 | I35: 0061423-79.2023.8.16.6000 | J35: CAPACITAÇÃO Espaço de Fala MULHERES TRANSEXUAIS E TRAVESTIS DEBATEM: VIOLÊNCIA E ACESSO À JUSTIÇA | W35: CEVID | AH35: Paraná | AI35: 2023 | AJ35: 45152 | AK35: 45152 | AL35: Certificado | AM35: transmissão ao vivo | AN35: Livre | AO35: 0.083333333 | AP35: 2 h | AQ35: 879 | AR35: https://ead.tjpr.jus.br/course/view.php?id=879 | AU35: Curso fechado | AX35: 20/09 - falei com o Jonatas q expediu os certificados | AY35: 581 - 586/2023 | BA35: 1 - LISTA GERAL_2020 A ... | BC35: 45189 | BI35: #VALUE! | BL35: 77
H36: 2023 | I36: 0102956-18.2023.8.16.6000 | J36: Masterclass de BIM para administração Publica | L36: EJUD | W36: Departamento de Engenharia e Arquitetura | AB36: CURSO | AF36: IN COMPANY | AI36: 2023 | AJ36: 45154 | AK36: 45156 | AU36: arquivado | AX36: 15/08/2023 - não contratado falta de tempo hábil | BA36: IN COMPANY | BI36: #VALUE!
H37: 2023 | I37: 0109501-07.2023.8.16.6000 | J37: Congresso 20 anos do Código Civil: avanços e novos desafios - Homenagem ao Ministro Paulo de Tarso Sanseverino | K37: DIVULGAÇÃO | L37: EJUD | Z37: administrativo | AI37: 2023 | AJ37: 45155 | AK37: 45156 | AU37: arquivado | BI37: #VALUE!
H38: 2023 | I38: 0079748-05.2023.8.16.6000 | J38: Fórum de Integridade do Judiciário Paranaense | L38: EJUD | AH38: Paraná | AI38: 2023 | AJ38: 45163 | AK38: 45163 | AL38: Certificado | AM38: webconferência | AO38: 0.29166667 | AP38: 7 h | AQ38: 871 | AR38: https://ead.tjpr.jus.br/course/view.php?id=871 | AU38: Curso fechado | AY38: 549-566/2023 | BA38: 1 - LISTA GERAL_2020 A ... | BC38: 45314 | BI38: #VALUE! | BL38: 336 | BP38: 1
H39: 2023 | I39: 0075436-83.2023.8.16.6000 | J39: Novas Fronteiras do Direito da Criança e do Adolescente | L39: EJUD | W39: CONSIJ | AH39: Paraná | AI39: 2023 | AJ39: 45168 | AK39: 45168 | AL39: Certificado | AM39: webconferência | AO39: 0.125 | AP39: 3 h | AQ39: 883 | AR39: https://ead.tjpr.jus.br/course/view.php?id=883 | AU39: Curso fechado | AX39: presencial e remoto | AY39: 567- 571/2023 | BA39: 1 - LISTA GERAL_2020 A ... | BC39: 45180 | BI39: #VALUE! | BL39: 124
H40: 2023 | I40: 0110053-69.2023.8.16.6000 | J40: Varas Especializadas em Direito Empresarial, Falências e Recuperação Judicial: Desempenho e Perspectivas | L40: EJUD | W40: P-GP-DG - Diretoria do Gabinete do Presidente | AH40: Paraná | AI40: 2023 | AJ40: 45168 | AK40: 45168 | AL40: Certificado | AM40: webconferência | AN40: Livre | AO40: 0.041666667 | AP40: 1 h | AQ40: 889 | AR40: https://ead.tjpr.jus.br/course/view.php?id=889 | AU40: Curso fechado | AY40: 572//2023 | BA40: 1 - LISTA GERAL_2020 A ... | BC40: 45180 | BI40: #VALUE! | BL40: 95
...

Sheet controle_matriz
A1: MODALIDADE | B1: ID DA PLANILHA | C1: ANO | D1: SEI | E1: NOME DO Curso | F1: conteúdo programatico | G1: NENHUMA CLASSIFICAÇÃO COPILOT | H1: Capacitação em Direitos Humanos, Gênero, Raça e Etnia; e em Depoimento Especial" - 0148945-13.2024.8.16.6000 | I1: Justiça Restaurativa - 0148919-15.2024.8.16.6000 | J1: Capacitação de Facilitadores 0148959-94.2024.8.16.6000 | K1: Acessibilidade e Inclusão - 0148938-21.2024.8.16.6000 | L1: Política de Prevenção e Enfrentamento do Assédio Moral, do Assédio Sexual e da Discriminação.0148908-83.2024.8.16.6000 | M1: SOCIOAMBIENTAL | N1: SUSTENTABILIDADE https://portal.tjpr.jus.br/portletforms/frm.do?idFormulario=7430 0017859-16.2024.8.16.6000 | O1: CURSO PARA MAGISTRADOS | P1: CATEGORIA DO Curso | Q1: RESPONSÁVEL PELA CERTIFICAÇÃO | R1: INSTITUIÇÃO DE ENSINO | S1: EMPRESA CONTRATADA | T1: CNPJ | U1: SEI DOC INSTRUTORES | V1: Intrutor (andamento do SEI) | W1: TERMO DE USO DE IMAGEM | X1: ATESTO | Y1: PRE ANOTAÇÃO ATESTO | Z1: REG DE INSTRUTORES | AA1: DESPESAS | AB1: VALOR DAS DESPESAS | AC1: PRODUÇÃO/UNIDADE SOLICITANTE | AD1: Eixo de Capacitação - Itinerários Formativos | AE1: PAE | AF1: INDICADORES | AG1: PORTARIA ENFAM | AH1: Tipo de evento | AI1: TURMA | AJ1: nº de vagas | AK1: INTÉRPRETES DE LIBRAS | AL1: MODALIDADE2 | AM1: PLANO DE CURSO/SEI | AN1: LOCAL | AO1: ANO DO CURSO2 | AP1: DATA INÍCIO | AQ1: DATA TERMINO | AR1: DECLARAÇÃO/ CERTIFICADO/ SEM CERTIFICAÇÃO | AS1: ON LINE OU PRESENCIAL | AT1: PUBLICO ALVO | AU1: RELATORIO_CARGA HORÁRIA | AV1: CARGA HORARIA | AW1: ID | AX1: ID do AVA novo | AY1: LINK AVA/ANDAMENTO DO CERTIFICADO | AZ1: lista de presença | BA1: SEI DOS INSCRITOS | BB1: STATUS | BC1: pronto para registro | BD1: DATA DA ULTIMA VERIFICAÇÃO | BE1: obs 2: | BF1: LIVRO DE REGISTRO | BG1: DATA DO ULTIMO REGISTRO | BH1: REG DE INSTRUTORES2 | BI1: REGISTRO DE INSTRUTORES NO SEI | BJ1: 2021 | BK1: 2022 | BL1: 2023 | BM1: REGISTRO NO SEI/2024 | BN1: 2024 | BO1: REGISTRO NO SEI/2025 | BP1: TOTAL CERTIFICADOS EMITIDOS/2025 | BQ1: 1º trim/2025 | BR1: 2º trim/2025 | BS1: 3º trim/2025 | BT1: 4º trim/2025
B2: 1 | C2: 1 | E2: 1° Curso de Formação de Laboratorista | AW2: 424 | BB2: Curso fechado | BP2: =Tabela3[[#This Row],[1º trim/2025]]+Tabela3[[#This Row],[2º trim/2025]]+Tabela3[[#This Row],[3º trim/2025]]+Tabela3[[#This Row],[4º trim/2025]] -> 0
B3: 2 | C3: 1 | E3: 10A/17CM - CURITIBA | AF3: MEDIAÇÃO | AI3: 10A/17CM - CURITIBA | AN3: CURITIBA | AW3: 111 | BB3: Curso fechado | BP3: =Tabela3[[#This Row],[1º trim/2025]]+Tabela3[[#This Row],[2º trim/2025]]+Tabela3[[#This Row],[3º trim/2025]]+Tabela3[[#This Row],[4º trim/2025]] -> 0
B4: 3 | C4: 1 | E4: 10A/18CM - CURITIBA | AF4: MEDIAÇÃO | AI4: 10A/18CM - CURITIBA | AN4: CURITIBA | AW4: 171 | BB4: Curso fechado | BP4: =Tabela3[[#This Row],[1º trim/2025]]+Tabela3[[#This Row],[2º trim/2025]]+Tabela3[[#This Row],[3º trim/2025]]+Tabela3[[#This Row],[4º trim/2025]] -> 0
B5: 4 | C5: 1 | E5: 10B/17CM - CURITIBA | AF5: MEDIAÇÃO | AI5: 10B/17CM - CURITIBA | AN5: CURITIBA | AW5: 112 | BB5: Curso fechado | BP5: =Tabela3[[#This Row],[1º trim/2025]]+Tabela3[[#This Row],[2º trim/2025]]+Tabela3[[#This Row],[3º trim/2025]]+Tabela3[[#This Row],[4º trim/2025]] -> 0
B6: 5 | C6: 1 | E6: 10B/18CM - CURITIBA | AF6: MEDIAÇÃO | AI6: 10B/18CM - CURITIBA | AN6: CURITIBA | AW6: 172 | BB6: Curso fechado | BP6: =Tabela3[[#This Row],[1º trim/2025]]+Tabela3[[#This Row],[2º trim/2025]]+Tabela3[[#This Row],[3º trim/2025]]+Tabela3[[#This Row],[4º trim/2025]] -> 0
B7: 6 | C7: 1 | E7: 11A/17CM - PONTA GROSSA | AF7: MEDIAÇÃO | AI7: 11A/17CM - PONTA GROSSA | AN7: PONTA GROSSA | AW7: 104 | BB7: Curso fechado | BP7: =Tabela3[[#This Row],[1º trim/2025]]+Tabela3[[#This Row],[2º trim/2025]]+Tabela3[[#This Row],[3º trim/2025]]+Tabela3[[#This Row],[4º trim/2025]] -> 0
B8: 7 | C8: 1 | E8: 11A/18CM - CURITIBA | AF8: MEDIAÇÃO | AI8: 11A/18CM - CURITIBA | AN8: CURITIBA | AW8: 176 | BB8: Curso fechado | BP8: =Tabela3[[#This Row],[1º trim/2025]]+Tabela3[[#This Row],[2º trim/2025]]+Tabela3[[#This Row],[3º trim/2025]]+Tabela3[[#This Row],[4º trim/2025]] -> 0
B9: 8 | C9: 1 | E9: 11B/18CM - CURITIBA | AF9: MEDIAÇÃO | AI9: 11B/18CM - CURITIBA | AN9: CURITIBA | AW9: 177 | BB9: Curso fechado | BP9: =Tabela3[[#This Row],[1º trim/2025]]+Tabela3[[#This Row],[2º trim/2025]]+Tabela3[[#This Row],[3º trim/2025]]+Tabela3[[#This Row],[4º trim/2025]] -> 0
B10: 9 | C10: 1 | E10: 12A/17CM - CIANORTE | AF10: MEDIAÇÃO | AI10: 12A/17CM - CIANORTE | AN10: CIANORTE | AW10: 107 | BB10: Curso fechado | BP10: =Tabela3[[#This Row],[1º trim/2025]]+Tabela3[[#This Row],[2º trim/2025]]+Tabela3[[#This Row],[3º trim/2025]]+Tabela3[[#This Row],[4º trim/2025]] -> 0
B11: 10 | C11: 1 | E11: 12A/18CM - CURITIBA | AF11: MEDIAÇÃO | AI11: 12A/18CM - CURITIBA | AN11: CURITIBA | AW11: 178 | BB11: Curso fechado | BP11: =Tabela3[[#This Row],[1º trim/2025]]+Tabela3[[#This Row],[2º trim/2025]]+Tabela3[[#This Row],[3º trim/2025]]+Tabela3[[#This Row],[4º trim/2025]] -> 0
B12: 11 | C12: 1 | E12: 12B/17CM - CIANORTE | AF12: MEDIAÇÃO | AI12: 12B/17CM - CIANORTE | AN12: CIANORTE | AW12: 108 | BB12: Curso fechado | BP12: =Tabela3[[#This Row],[1º trim/2025]]+Tabela3[[#This Row],[2º trim/2025]]+Tabela3[[#This Row],[3º trim/2025]]+Tabela3[[#This Row],[4º trim/2025]] -> 0
B13: 12 | C13: 1 | E13: 12B/18CM - CURITIBA | AF13: MEDIAÇÃO | AI13: 12B/18CM - CURITIBA | AN13: CURITIBA | AW13: 179 | BB13: Curso fechado | BP13: =Tabela3[[#This Row],[1º trim/2025]]+Tabela3[[#This Row],[2º trim/2025]]+Tabela3[[#This Row],[3º trim/2025]]+Tabela3[[#This Row],[4º trim/2025]] -> 0
B14: 13 | C14: 1 | E14: 13A/17CM - CURITIBA | AF14: MEDIAÇÃO | AI14: 13A/17CM - CURITIBA | AN14: CURITIBA | AW14: 110 | BB14: Curso fechado | BP14: =Tabela3[[#This Row],[1º trim/2025]]+Tabela3[[#This Row],[2º trim/2025]]+Tabela3[[#This Row],[3º trim/2025]]+Tabela3[[#This Row],[4º trim/2025]] -> 0
... B43: 42 | C43: 1 | E43: 1A/18CM - CURITIBA | AF43: MEDIAÇÃO | AI43: 1A/18CM - CURITIBA | AN43: CURITIBA | AW43: 137 | BB43: Curso fechado | BP43: =Tabela3[[#This Row],[1º trim/2025]]+Tabela3[[#This Row],[2º trim/2025]]+Tabela3[[#This Row],[3º trim/2025]]+Tabela3[[#This Row],[4º trim/2025]] -> 0
B44: 43 | C44: 1 | E44: 2024 _ Brigada _ Etapa Prática-Certificado de Brigadista _ Jandaia do Sul | AF44: BRIGADISTA | AN44: Jandaia do Sul | AW44: 954 | AY44: https://ead.tjpr.jus.br/course/view.php?id=954 | BB44: Curso fechado | BP44: =Tabela3[[#This Row],[1º trim/2025]]+Tabela3[[#This Row],[2º trim/2025]]+Tabela3[[#This Row],[3º trim/2025]]+Tabela3[[#This Row],[4º trim/2025]] -> 0
B45: 44 | C45: 1 | E45: 2024 _ Brigada _ Etapa Prática-Certificado de Brigadista _ Cruzeiro do Oeste | AF45: BRIGADISTA | AN45: Cruzeiro do Oeste | AW45: 954 | AY45: https://ead.tjpr.jus.br/course/view.php?id=954 | BB45: Curso fechado | BP45: =Tabela3[[#This Row],[1º trim/2025]]+Tabela3[[#This Row],[2º trim/2025]]+Tabela3[[#This Row],[3º trim/2025]]+Tabela3[[#This Row],[4º trim/2025]] -> 0
B46: 45 | C46: 1 | E46: 2024 _ Brigada _ Etapa Prática-Certificado de Brigadista _ Palácio do Tribunal de Justiça | AF46: BRIGADISTA | AN46: Palácio do Tribunal de Justiça | AW46: 954 | AY46: https://ead.tjpr.jus.br/course/view.php?id=954 | BB46: Curso fechado | BP46: =Tabela3[[#This Row],[1º trim/2025]]+Tabela3[[#This Row],[2º trim/2025]]+Tabela3[[#This Row],[3º trim/2025]]+Tabela3[[#This Row],[4º trim/2025]] -> 0
B47: 46 | C47: 1 | E47: 20A/17CM - TOLEDO | AF47: MEDIAÇÃO | AI47: 20A/17CM - TOLEDO | AN47: TOLEDO | AW47: 133 | BB47: Curso fechado | BP47: =Tabela3[[#This Row],[1º trim/2025]]+Tabela3[[#This Row],[2º trim/2025]]+Tabela3[[#This Row],[3º trim/2025]]+Tabela3[[#This Row],[4º trim/2025]] -> 0
B48: 47 | C48: 1 | E48: 20A/18CM - CURITIBA | AF48: MEDIAÇÃO | AI48: 20A/18CM - CURITIBA | AN48: CURITIBA | AW48: 209 | BB48: Curso fechado | BP48: =Tabela3[[#This Row],[1º trim/2025]]+Tabela3[[#This Row],[2º trim/2025]]+Tabela3[[#This Row],[3º trim/2025]]+Tabela3[[#This Row],[4º trim/2025]] -> 0
B49: 48 | C49: 1 | E49: 20B/17CM - TOLEDO | AF49: MEDIAÇÃO | AI49: 20B/17CM - TOLEDO | AN49: TOLEDO | AW49: 134 | BB49: Curso fechado | BP49: =Tabela3[[#This Row],[1º trim/2025]]+Tabela3[[#This Row],[2º trim/2025]]+Tabela3[[#This Row],[3º trim/2025]]+Tabela3[[#This Row],[4º trim/2025]] -> 0
B50: 49 | C50: 1 | E50: 21A/17CM - LONDRINA | AF50: MEDIAÇÃO | AI50: 21A/17CM - LONDRINA | AN50: Londrina | AW50: 124 | BB50: Curso fechado | BP50: =Tabela3[[#This Row],[1º trim/2025]]+Tabela3[[#This Row],[2º trim/2025]]+Tabela3[[#This Row],[3º trim/2025]]+Tabela3[[#This Row],[4º trim/2025]] -> 0
B51: 50 | C51: 1 | E51: 21B/17CM - LONDRINA | AF51: MEDIAÇÃO | AI51: 21B/17CM - LONDRINA | AN51: Londrina | AW51: 125 | BB51: Curso fechado | BP51: =Tabela3[[#This Row],[1º trim/2025]]+Tabela3[[#This Row],[2º trim/2025]]+Tabela3[[#This Row],[3º trim/2025]]+Tabela3[[#This Row],[4º trim/2025]] -> 0
B52: 51 | C52: 1 | E52: 22A/17CM - MARINGÁ | AF52: MEDIAÇÃO | AI52: 22A/17CM - MARINGÁ | AN52: Maringá | AW52: 131 | BB52: Curso fechado | BP52: =Tabela3[[#This Row],[1º trim/2025]]+Tabela3[[#This Row],[2º trim/2025]]+Tabela3[[#This Row],[3º trim/2025]]+Tabela3[[#This Row],[4º trim/2025]] -> 0
B53: 52 | C53: 1 | E53: 22A/18CM - CURITIBA | AF53: MEDIAÇÃO | AI53: 22A/18CM - CURITIBA | AN53: CURITIBA | AW53: 224 | BB53: Curso fechado | BP53: =Tabela3[[#This Row],[1º trim/2025]]+Tabela3[[#This Row],[2º trim/2025]]+Tabela3[[#This Row],[3º trim/2025]]+Tabela3[[#This Row],[4º trim/2025]] -> 0
B54: 53 | C54: 1 | E54: 22B/17CM - MARINGÁ | AF54: MEDIAÇÃO | AI54: 22B/17CM - MARINGÁ | AN54: Maringá | AW54: 132 | BB54: Curso fechado | BP54: =Tabela3[[#This Row],[1º trim/2025]]+Tabela3[[#This Row],[2º trim/2025]]+Tabela3[[#This Row],[3º trim/2025]]+Tabela3[[#This Row],[4º trim/2025]] -> 0
B55: 54 | C55: 1 | E55: 22B/18CM - CURITIBA | AF55: MEDIAÇÃO | AI55: 22B/18CM - CURITIBA | AN55: CURITIBA | AW55: 226 | BB55: Curso fechado | BP55: =Tabela3[[#This Row],[1º trim/2025]]+Tabela3[[#This Row],[2º trim/2025]]+Tabela3[[#This Row],[3º trim/2025]]+Tabela3[[#This Row],[4º trim/2025]] -> 0
B56: 55 | C56: 1 | E56: 22C/18CM - CURITIBA | AF56: MEDIAÇÃO | AI56: 22C/18CM - CURITIBA | AN56: CURITIBA | AW56: 229 | BB56: Curso fechado | BP56: =Tabela3[[#This Row],[1º trim/2025]]+Tabela3[[#This Row],[2º trim/2025]]+Tabela3[[#This Row],[3º trim/2025]]+Tabela3[[#This Row],[4º trim/2025]] -> 0
B57: 56 | C57: 1 | E57: 23A/17CM - CASCAVEL | AF57: MEDIAÇÃO | AI57: 23A/17CM - CASCAVEL | AN57: Cascavel | AW57: 136 | BB57: Curso fechado | BP57: =Tabela3[[#This Row],[1º trim/2025]]+Tabela3[[#This Row],[2º trim/2025]]+Tabela3[[#This Row],[3º trim/2025]]+Tabela3[[#This Row],[4º trim/2025]] -> 0
B58: 57 | C58: 1 | E58: 23A/18CM - CURITIBA | AF58: MEDIAÇÃO | AI58: 23A/18CM - CURITIBA | AN58: CURITIBA | AW58: 211 | BB58: Curso fechado | BP58: =Tabela3[[#This Row],[1º trim/2025]]+Tabela3[[#This Row],[2º trim/2025]]+Tabela3[[#This Row],[3º trim/2025]]+Tabela3[[#This Row],[4º trim/2025]] -> 0
... B70: 69 | C70: 1 | E70: 2C/17CM - CURITIBA | AF70: MEDIAÇÃO | AI70: 2C/17CM - CURITIBA | AN70: CURITIBA | AW70: 82 | BB70: Curso fechado | BP70: =Tabela3[[#This Row],[1º trim/2025]]+Tabela3[[#This Row],[2º trim/2025]]+Tabela3[[#This Row],[3º trim/2025]]+Tabela3[[#This Row],[4º trim/2025]] -> 0
B71: 70 | C71: 1 | E71: 2º Seminário Nacional sobre a Atuação da Assessoria Jurídica em Licitações e Contratos e suas Boas Práticas | AN71: Práticas | AW71: 515 | BB71: Curso fechado | BP71: =Tabela3[[#This Row],[1º trim/2025]]+Tabela3[[#This Row],[2º trim/2025]]+Tabela3[[#This Row],[3º trim/2025]]+Tabela3[[#This Row],[4º trim/2025]] -> 0
B72: 71 | C72: 1 | E72: 30A/18CM - FRANCISCO BELTRÃO | AF72: MEDIAÇÃO | AI72: 30A/18CM - FRANCISCO BELTRÃO | AN72: Francisco Beltrão | AW72: 234 | BB72: Curso fechado | BP72: =Tabela3[[#This Row],[1º trim/2025]]+Tabela3[[#This Row],[2º trim/2025]]+Tabela3[[#This Row],[3º trim/2025]]+Tabela3[[#This Row],[4º trim/2025]] -> 0
B73: 72 | C73: 1 | E73: 31A/18CM - CEJUSC 2º GRAU | AF73: MEDIAÇÃO | AI73: 31A/18CM - CEJUSC 2º GRAU | AN73: CEJUSC 2º GRAU | AW73: 248 | BB73: Curso fechado | BP73: =Tabela3[[#This Row],[1º trim/2025]]+Tabela3[[#This Row],[2º trim/2025]]+Tabela3[[#This Row],[3º trim/2025]]+Tabela3[[#This Row],[4º trim/2025]] -> 0
B74: 73 | C74: 1 | E74: 31B/18CM - CEJUSC 2º GRAU | AF74: MEDIAÇÃO | AI74: 31B/18CM - CEJUSC 2º GRAU | AN74: CEJUSC 2º GRAU | AW74: 249 | BB74: Curso fechado | BP74: =Tabela3[[#This Row],[1º trim/2025]]+Tabela3[[#This Row],[2º trim/2025]]+Tabela3[[#This Row],[3º trim/2025]]+Tabela3[[#This Row],[4º trim/2025]] -> 0
B75: 74 | C75: 1 | E75: 32A/18CM - REALEZA | AF75: MEDIAÇÃO | AI75: 32A/18CM - REALEZA | AN75: REALEZA | AW75: 242 | BB75: Curso fechado | BP75: =Tabela3[[#This Row],[1º trim/2025]]+Tabela3[[#This Row],[2º trim/2025]]+Tabela3[[#This Row],[3º trim/2025]]+Tabela3[[#This Row],[4º trim/2025]] -> 0
B76: 75 | C76: 1 | E76: 33A/18CM - IRATI | AF76: MEDIAÇÃO | AI76: 33A/18CM - IRATI | AN76: IRATI | AW76: 250 | BB76: Curso fechado | BP76: =Tabela3[[#This Row],[1º trim/2025]]+Tabela3[[#This Row],[2º trim/2025]]+Tabela3[[#This Row],[3º trim/2025]]+Tabela3[[#This Row],[4º trim/2025]] -> 0
B77: 76 | C77: 1 | E77: 33B/18CM - IRATI | AF77: MEDIAÇÃO | AI77: 33B/18CM - IRATI | AN77: IRATI | AW77: 251 | BB77: Curso fechado | BP77: =Tabela3[[#This Row],[1º trim/2025]]+Tabela3[[#This Row],[2º trim/2025]]+Tabela3[[#This Row],[3º trim/2025]]+Tabela3[[#This Row],[4º trim/2025]] -> 0
B78: 77 | C78: 1 | E78: 34A/18CM - MARINGÁ | AF78: MEDIAÇÃO | AI78: 34A/18CM - MARINGÁ | AN78: Maringá | AW78: 257 | BB78: Curso fechado | BP78: =Tabela3[[#This Row],[1º trim/2025]]+Tabela3[[#This Row],[2º trim/2025]]+Tabela3[[#This Row],[3º trim/2025]]+Tabela3[[#This Row],[4º trim/2025]] -> 0
B79: 78 | C79: 1 | E79: 34B/18CM - MARINGÁ | AF79: MEDIAÇÃO | AI79: 34B/18CM - MARINGÁ | AN79: Maringá | AW79: 256 | BB79: Curso fechado | BP79: =Tabela3[[#This Row],[1º trim/2025]]+Tabela3[[#This Row],[2º trim/2025]]+Tabela3[[#This Row],[3º trim/2025]]+Tabela3[[#This Row],[4º trim/2025]] -> 0
...

Sheet autoistrucionais
B1: MODALIDADE | C1: ID DA PLANILHA | D1: ANO | E1: SEI | F1: NOME DO Curso | G1: ID | H1: LINK AVA/ANDAMENTO DO CERTIFICADO | I1: STATUS
B2: =VLOOKUP("autoinstrucional",controle_matriz!A:A,0,FALSE) -> #VALUE! | C2: 422 | D2: 2019 | E2: 0034789-85.2019.8.16.6000 | F2: Proservidor - Agentes Delegados - SDP | G2: 620 | H2: https://ead.tjpr.jus.br/course/view.php?id=620
B3: =VLOOKUP("autoinstrucional",controle_matriz!A:A,0,FALSE) -> #VALUE! | C3: 432 | D3: 2019 | E3: 0062050-25.2019.8.16.6000 | F3: Nivelamento dos Servidores do Poder Judiciário | G3: 355 | H3: https://ead.tjpr.jus.br/course/view.php?id=355
A4: {=_xlfn._xlws.FILTER(controle_matriz!A:A,controle_matriz!A:A="autoistrucional","")} | B4: =VLOOKUP("autoinstrucional",controle_matriz!A:A,0,FALSE) -> #VALUE! | C4: 439 | D4: 2019 | E4: 0082087-73.2019.8.16.6000 | F4: Crase | G4: 378 | H4: https://ead.tjpr.jus.br/course/view.php?id=378
A5: {=_xlfn._xlws.FILTER(controle_matriz!A:A,controle_matriz!A:A="autoistrucional","")} | B5: =VLOOKUP("autoinstrucional",controle_matriz!A:A,0,FALSE) -> #VALUE! | C5: 451 | D5: 2020 | E5: 0009727-09.2020.8.16.6000 | F5: Habilidades sociais no trabalho | G5: 429 | H5: https://ead.tjpr.jus.br/course/view.php?id=429
A6: {=_xlfn._xlws.FILTER(controle_matriz!A:A,controle_matriz!A:A="autoistrucional","")} | B6: =VLOOKUP("autoinstrucional",controle_matriz!A:A,0,FALSE) -> #VALUE! | C6: 453 | D6: 2020 | E6: 0011322-43.2020.8.16.6000 | F6: Proservidor - Cartório Distribuidor | G6: 384 | H6: https://ead.tjpr.jus.br/course/view.php?id=384
A7: {=_xlfn._xlws.FILTER(controle_matriz!A:A,controle_matriz!A:A="autoistrucional","")} | B7: =VLOOKUP("autoinstrucional",controle_matriz!A:A,0,FALSE) -> #VALUE! | C7: 463 | D7: 2020 | E7: 0030036-51.2020.8.16.6000 | F7: Tríade da Felicidade | G7: 492 | H7: https://ead.tjpr.jus.br/course/view.php?id=492
A8: {=_xlfn._xlws.FILTER(controle_matriz!A:A,controle_matriz!A:A="autoistrucional","")} | B8: =VLOOKUP("autoinstrucional",controle_matriz!A:A,0,FALSE) -> #VALUE! | C8: 464 | D8: 2020 | E8: 0033257-81.2016.8.16.6000 | F8: Nome Social - Identidade, Reconhecimento e Memória | G8: 417 | H8: https://ead.tjpr.jus.br/course/view.php?id=417
A9: {=_xlfn._xlws.FILTER(controle_matriz!A:A,controle_matriz!A:A="autoistrucional","")} | B9: =VLOOKUP("autoinstrucional",controle_matriz!A:A,0,FALSE) -> #VALUE! | C9: 477 | D9: 2020 | E9: 0060521-68.2019.8.16.6000 | F9: Sistema Eletrônico de Execução Unificado- SEEU | G9: 409 | H9: https://ead.tjpr.jus.br/course/view.php?id=409
A10: {=_xlfn._xlws.FILTER(controle_matriz!A:A,controle_matriz!A:A="autoistrucional","")} | B10: =VLOOKUP("autoinstrucional",controle_matriz!A:A,0,FALSE) -> #VALUE! | C10: 481 | D10: 2020 | E10: 0074115-23.2017.8.16.6000 | F10: Calculadora Judicial Agnesi | G10: 528 | H10: https://ead.tjpr.jus.br/course/view.php?id=528
A11: {=_xlfn._xlws.FILTER(controle_matriz!A:A,controle_matriz!A:A="autoistrucional","")} | B11: =VLOOKUP("autoinstrucional",controle_matriz!A:A,0,FALSE) -> #VALUE! | C11: 501 | D11: 2021 | E11: 0003414-32.2020.8.16.6000 | F11: Teletrabalho - 3ª Edição | G11: 655 | H11: https://ead.tjpr.jus.br/course/view.php?id=655
A12: {=_xlfn._xlws.FILTER(controle_matriz!A:A,controle_matriz!A:A="autoistrucional","")} | B12: =VLOOKUP("autoinstrucional",controle_matriz!A:A,0,FALSE) -> #VALUE! | C12: 502 | D12: 2021 | E12: 0003689-78.2020.8.16.6000 | F12: Regras Práticas da Nova Ortografia - 5ª edição | G12: 426
A13: {=_xlfn._xlws.FILTER(controle_matriz!A:A,controle_matriz!A:A="autoistrucional","")} | B13: =VLOOKUP("autoinstrucional",controle_matriz!A:A,0,FALSE) -> #VALUE! | C13: 615 | D13: 2021 | E13: 0003706-17.2020.8.16.6000 | F13: SEI - Sistema Eletrônico de Informações | G13: 427 | H13: https://ead.tjpr.jus.br/course/view.php?id=427
A14: {=_xlfn._xlws.FILTER(controle_matriz!A:A,controle_matriz!A:A="autoistrucional","")} | B14: =VLOOKUP("autoinstrucional",controle_matriz!A:A,0,FALSE) -> #VALUE! | C14: 507 | D14: 2021 | E14: 0013203-89.2019.8.16.6000 | F14: Precatório e Requisição de Pequeno Valor | G14: 585 | H14: https://ead.tjpr.jus.br/course/view.php?id=585
A15: {=_xlfn._xlws.FILTER(controle_matriz!A:A,controle_matriz!A:A="autoistrucional","")} | B15: =VLOOKUP("autoinstrucional",controle_matriz!A:A,0,FALSE) -> #VALUE! | C15: 509 | D15: 2021 | E15: 0014757-88.2021.8.16.6000 | F15: Formação de Gestores Liderança, Gestão e Indicadores de Desempenho | G15: 532 | H15: https://ead.tjpr.jus.br/course/view.php?id=532
A16: {=_xlfn._xlws.FILTER(controle_matriz!A:A,controle_matriz!A:A="autoistrucional","")} | B16: =VLOOKUP("autoinstrucional",controle_matriz!A:A,0,FALSE) -> #VALUE! | C16: 511 | D16: 2021 | E16: 0015797-03.2024.8.16.6000 | F16: Gestão Documental no Poder Judiciário | G16: 376 | H16: https://ead.tjpr.jus.br/course/view.php?id=376
A17: {=_xlfn._xlws.FILTER(controle_matriz!A:A,controle_matriz!A:A="autoistrucional","")} | B17: =VLOOKUP("autoinstrucional",controle_matriz!A:A,0,FALSE) -> #VALUE! | C17: 515 | D17: 2021 | E17: 0023891-76.2020.8.16.6000 | F17: Fundo Rotativo | G17: 297 | H17: https://ead.tjpr.jus.br/course/view.php?id=297
A18: {=_xlfn._xlws.FILTER(controle_matriz!A:A,controle_matriz!A:A="autoistrucional","")} | B18: =VLOOKUP("autoinstrucional",controle_matriz!A:A,0,FALSE) -> #VALUE! | C18: 545 | D18: 2021 | E18: 0064934-61.2018.8.16.6000 | F18: Acessibilidade e Inclusão no TJPR | G18: 617 | H18: https://ead.tjpr.jus.br/course/view.php?id=617
A19: {=_xlfn._xlws.FILTER(controle_matriz!A:A,controle_matriz!A:A="autoistrucional","")} | B19: =VLOOKUP("autoinstrucional",controle_matriz!A:A,0,FALSE) -> #VALUE! | C19: 546 | D19: 2021 | E19: 0064934-61.2018.8.16.6000 | F19: Conhecendo o Poder Judiciário | G19: 533 | H19: https://ead.tjpr.jus.br/course/view.php?id=533
A20: {=_xlfn._xlws.FILTER(controle_matriz!A:A,controle_matriz!A:A="autoistrucional","")} | B20: =VLOOKUP("autoinstrucional",controle_matriz!A:A,0,FALSE) -> #VALUE! | C20: 547 | D20: 2021 | E20: 0064934-61.2018.8.16.6000 | F20: Gestão por Competências | G20: 487 | H20: https://ead.tjpr.jus.br/course/view.php?id=487
A21: {=_xlfn._xlws.FILTER(controle_matriz!A:A,controle_matriz!A:A="autoistrucional","")} | B21: =VLOOKUP("autoinstrucional",controle_matriz!A:A,0,FALSE) -> #VALUE! | C21: 552 | D21: 2021 | E21: 0072085-73.2021.8.16.6000 | F21: A Violência Doméstica, suas relações com ações cíveis em matéria de família e o atendimento humanizado | G21: 665 e 545 | H21: https://ead.tjpr.jus.br/course/view.php?id=665
A22: {=_xlfn._xlws.FILTER(controle_matriz!A:A,controle_matriz!A:A="autoistrucional","")} | B22: =VLOOKUP("autoinstrucional",controle_matriz!A:A,0,FALSE) -> #VALUE! | C22: 563 | D22: 2021 | E22: 0080451-38.2020.8.16.6000 | F22: Lei de Introdução às Normas do Direito Brasileiro | G22: 521 | H22: https://ead.tjpr.jus.br/course/view.php?id=521
A23: {=_xlfn._xlws.FILTER(controle_matriz!A:A,controle_matriz!A:A="autoistrucional","")} | B23: =VLOOKUP("autoinstrucional",controle_matriz!A:A,0,FALSE) -> #VALUE! | C23: 578 | D23: 2021 | E23: 0092653-13.2021.8.16.6000 | F23: Avaliação de Imóveis para Oficiais de Justiça e Cumpridores de Mandados | G23: 601 | H23: https://ead.tjpr.jus.br/course/view.php?id=601
A24: {=_xlfn._xlws.FILTER(controle_matriz!A:A,controle_matriz!A:A="autoistrucional","")} | B24: =VLOOKUP("autoinstrucional",controle_matriz!A:A,0,FALSE) -> #VALUE! | C24: 609 | D24: 2021 | E24: 0120406-76.2020.8.16.6000 | F24: Formação de novos professores da ginástica laboral | G24: 541 | H24: https://ead.tjpr.jus.br/course/view.php?id=541
A25: {=_xlfn._xlws.FILTER(controle_matriz!A:A,controle_matriz!A:A="autoistrucional","")} | B25: =VLOOKUP("autoinstrucional",controle_matriz!A:A,0,FALSE) -> #VALUE! | C25: 617 | D25: 2022 | E25: 0008308-85.2019.8.16.6000 | F25: Gestão de Precedentes | G25: 475 | H25: https://ead.tjpr.jus.br/course/view.php?id=475
A26: {=_xlfn._xlws.FILTER(controle_matriz!A:A,controle_matriz!A:A="autoistrucional","")} | B26: =VLOOKUP("autoinstrucional",controle_matriz!A:A,0,FALSE) -> #VALUE! | C26: 623 | D26: 2022 | E26: 0013762-41.2022.8.16.6000 | F26: Funções do Assistente da Direção de Fórum relacionadas ao Departamento de Gestão de Serviços Terceirizados | G26: 742 | H26: https://ead.tjpr.jus.br/course/view.php?id=742
A27: {=_xlfn._xlws.FILTER(controle_matriz!A:A,controle_matriz!A:A="autoistrucional","")} | B27: =VLOOKUP("autoinstrucional",controle_matriz!A:A,0,FALSE) -> #VALUE! | C27: 628 | D27: 2022 | E27: 0015995-11.2022.8.16.6000 | F27: Formação de secretários e secretárias das sessões de julgamento | G27: 690 | H27: https://ead.tjpr.jus.br/course/view.php?id=690
A28: {=_xlfn._xlws.FILTER(controle_matriz!A:A,controle_matriz!A:A="autoistrucional","")} | B28: =VLOOKUP("autoinstrucional",controle_matriz!A:A,0,FALSE) -> #VALUE! | C28: 663 | D28: 2022 | E28: 0026507-53.2022.8.16.6000 | F28: PROGRAMA JUSTIÇA 4.0 DPPJ - CNJ | G28: 715 | H28: https://ead.tjpr.jus.br/course/view.php?id=715
A29: {=_xlfn._xlws.FILTER(controle_matriz!A:A,controle_matriz!A:A="autoistrucional","")} | B29: =VLOOKUP("autoinstrucional",controle_matriz!A:A,0,FALSE) -> #VALUE! | C29: 665 | D29: 2022 | E29: 0031499-28.2020.8.16.6000 | F29: Proservidor - Unidade Cível | G29: 649 | H29: https://ead.tjpr.jus.br/course/view.php?id=649
A30: {=_xlfn._xlws.FILTER(controle_matriz!A:A,controle_matriz!A:A="autoistrucional","")} | B30: =VLOOKUP("autoinstrucional",controle_matriz!A:A,0,FALSE) -> #VALUE! | C30: 768 | D30: 2022 | E30: 0108225-09.2021.8.16.6000 | F30: Curso de Introdução à Justiça Restaurativa - Formação Teórica - 30h | G30: 693 | H30: https://ead.tjpr.jus.br/course/view.php?id=693
A31: {=_xlfn._xlws.FILTER(controle_matriz!A:A,controle_matriz!A:A="autoistrucional","")} | B31: =VLOOKUP("autoinstrucional",controle_matriz!A:A,0,FALSE) -> #VALUE! | C31: 772 | D31: 2022 | E31: 0111591-22.2022.8.16.6000 | F31: Curso teórico de Brigadistas | G31: 729 | H31: https://ead.tjpr.jus.br/course/view.php?id=729
A32: {=_xlfn._xlws.FILTER(controle_matriz!A:A,controle_matriz!A:A="autoistrucional","")} | B32: =VLOOKUP("autoinstrucional",controle_matriz!A:A,0,FALSE) -> #VALUE! | C32: 776 | D32: 2022 | E32: 0113724-37.2022.8.16.6000 | F32: Gestão de Conflitos | G32: 803 | H32: https://ead.tjpr.jus.br/course/view.php?id=803
A33: {=_xlfn._xlws.FILTER(controle_matriz!A:A,controle_matriz!A:A="autoistrucional","")} | B33: =VLOOKUP("autoinstrucional",controle_matriz!A:A,0,FALSE) -> #VALUE! | C33: 777 | D33: 2022 | E33: 0114783-94.2021.8.16.6000 | F33: Código de Ética e Conduta dos servidores e demais colaboradores do Poder Judiciário do Estado do Paraná | G33: 697 | H33: https://ead.tjpr.jus.br/course/view.php?id=697
... A40: {=_xlfn._xlws.FILTER(controle_matriz!A:A,controle_matriz!A:A="autoistrucional","")} | B40: =VLOOKUP("autoinstrucional",controle_matriz!A:A,0,FALSE) -> #VALUE! | C40: 987 | D40: 2024 | E40: 0013494-50.2023.8.16.6000 | F40: Unindo esforços contra a violência doméstica e familiar - Turma 2 | G40: 681 | H40: https://ead.tjpr.jus.br/course/view.php?id=681
A41: {=_xlfn._xlws.FILTER(controle_matriz!A:A,controle_matriz!A:A="autoistrucional","")} | B41: =VLOOKUP("autoinstrucional",controle_matriz!A:A,0,FALSE) -> #VALUE! | C41: 1028 | D41: 2024 | E41: 0040184-82.2024.8.16.6000 | F41: Gestão Aplicada às Unidades Judiciais (SEMPs) | G41: 1003
A42: {=_xlfn._xlws.FILTER(controle_matriz!A:A,controle_matriz!A:A="autoistrucional","")} | B42: =VLOOKUP("autoinstrucional",controle_matriz!A:A,0,FALSE) -> #VALUE! | C42: 1033 | D42: 2024 | E42: 0043367-95.2023.8.16.6000 | F42: CURSO DE APERFEIÇOAMENTO PARA SERVIDORES E SERVIDORAS E ASSESSORES E ASSESSORAS ATUANTES NA JURISDIÇÃO DA INFÂNCIA E JUVENTUDE | G42: 981 | H42: https://ead.tjpr.jus.br/course/view.php?id=981
A43: {=_xlfn._xlws.FILTER(controle_matriz!A:A,controle_matriz!A:A="autoistrucional","")} | B43: =VLOOKUP("autoinstrucional",controle_matriz!A:A,0,FALSE) -> #VALUE! | C43: 1056 | D43: 2024 | E43: 0061954-34.2024.8.16.6000 | F43: INTRODUÇÃO DOS PROFISSIONAIS DAS ÁREAS DE PSICOLOGIA E SERVIÇO SOCIAL NO ÂMBITO DO PODER JUDICIÁRIO DO PARANÁ NAS ÁREAS DE FAMÍLIA, INFÂNCIA E JUVENTUDE E VIOLÊNCIA DOMÉSTICA E FAMILIAR | G43: 978 | H43: https://ead.tjpr.jus.br/course/view.php?id=978
A44: {=_xlfn._xlws.FILTER(controle_matriz!A:A,controle_matriz!A:A="autoistrucional","")} | B44: =VLOOKUP("autoinstrucional",controle_matriz!A:A,0,FALSE) -> #VALUE! | C44: 1058 | D44: 2024 | E44: 0063696-31.2023.8.16.6000 | F44: Projudi digital: efetividade e produtividade | G44: 958 | H44: https://ead.tjpr.jus.br/course/view.php?id=958
A45: {=_xlfn._xlws.FILTER(controle_matriz!A:A,controle_matriz!A:A="autoistrucional","")} | B45: =VLOOKUP("autoinstrucional",controle_matriz!A:A,0,FALSE) -> #VALUE! | C45: 1364 | D45: 2024 | E45: 0080329-83.2024.8.16.6000 | F45: I Jornada CEVID Orienta – Conhecendo o Programa | G45: 975 | H45: https://ead.tjpr.jus.br/course/view.php?id=975
A46: {=_xlfn._xlws.FILTER(controle_matriz!A:A,controle_matriz!A:A="autoistrucional","")} | B46: =VLOOKUP("autoinstrucional",controle_matriz!A:A,0,FALSE) -> #VALUE! | C46: 1082 | D46: 2024 | E46: 0089071-34.2023.8.16.6000 | F46: Sistema Distribuidor do Paraná (SDP). | G46: 1030
...

Sheet Sandro-informação simplificada
A1: {=Tabela3[[#Headers],[MODALIDADE]:[NOME DO Curso]]} -> MODALIDADE | B1: ID DA PLANILHA | C1: ANO | D1: SEI | E1: NOME DO Curso | F1: NENHUMA CLASSIFICAÇÃO COPILOT | G1: Capacitação em Direitos Humanos, Gênero, Raça e Etnia; e em Depoimento Especial" - 0148945-13.2024.8.16.6000 | H1: Justiça Restaurativa - 0148919-15.2024.8.16.6000 | I1: Capacitação de Facilitadores 0148959-94.2024.8.16.6000 | J1: Acessibilidade e Inclusão - 0148938-21.2024.8.16.6000 | K1: Política de Prevenção e Enfrentamento do Assédio Moral, do Assédio Sexual e da Discriminação.0148908-83.2024.8.16.6000 | L1: SOCIOAMBIENTAL | M1: SUSTENTABILIDADE https://portal.tjpr.jus.br/portletforms/frm.do?idFormulario=7430 0017859-16.2024.8.16.6000 | N1: CURSO PARA MAGISTRADOS | O1: LIVRO DE REGISTRO | P1: DATA DO ULTIMO REGISTRO | Q1: REG DE INSTRUTORES2 | R1: REGISTRO DE INSTRUTORES NO SEI | S1: 2021 | T1: 2022 | U1: 2023 | V1: REGISTRO NO SEI/2024 | W1: 2024 | X1: REGISTRO NO SEI/2025 | Y1: TOTAL CERTIFICADOS EMITIDOS/2025 | Z1: 1º trim/2025 | AA1: 2º trim/2025 | AB1: 3º trim/2025 | AC1: 4º trim/2025
A2: =Tabela3[[#This Row],[MODALIDADE]] -> 0 | B2: =Tabela3[[#This Row],[ID DA PLANILHA]] -> 1 | C2: =Tabela3[[#This Row],[ANO]] -> 1 | D2: =Tabela3[[#This Row],[SEI]] -> 0 | E2: =Tabela3[[#This Row],[NOME DO Curso]] -> 1° Curso de Formação de Laboratorista | F2: =Tabela3[[#This Row],[NENHUMA CLASSIFICAÇÃO COPILOT]] -> 0 | G2: =Tabela3[[#This Row],[Capacitação em Direitos Humanos, Gênero, Raça e Etnia; e em Depoimento Especial" - 0148945-13.2024.8.16.6000]] -> 0 | H2: =Tabela3[[#This Row],[Justiça Restaurativa - 0148919-15.2024.8.16.6000]] -> 0 | I2: =Tabela3[[#This Row],[Capacitação de Facilitadores 0148959-94.2024.8.16.6000]] -> 0 | J2: =Tabela3[[#This Row],[Acessibilidade e Inclusão - 0148938-21.2024.8.16.6000]] -> 0 | K2: =Tabela3[[#This Row],[Política de Prevenção e Enfrentamento do Assédio Moral, do Assédio Sexual e da Discriminação.0148908-83.2024.8.16.6000]] -> 0 | L2: =Tabela3[[#This Row],[SOCIOAMBIENTAL]] -> 0 | M2: =Tabela3[[#This Row],[SUSTENTABILIDADE https://portal.tjpr.jus.br/portletforms/frm.do?idFormulario=7430 0017859-16.2024.8.16.6000]] -> 0 | N2: =Tabela3[[#This Row],[CURSO PARA MAGISTRADOS]] -> 0 | O2: =Tabela3[[#This Row],[LIVRO DE REGISTRO]] -> 0 | P2: =Tabela3[[#This Row],[DATA DO ULTIMO REGISTRO]] -> 0 | Q2: =Tabela3[[#This Row],[REG DE INSTRUTORES2]] -> 0 | R2: =Tabela3[[#This Row],[REGISTRO DE INSTRUTORES NO SEI]] -> 0 | S2: =Tabela3[[#This Row],[2021]] -> 0 | T2: =Tabela3[[#This Row],[2022]] -> 0 | U2: =Tabela3[[#This Row],[2023]] -> 0 | V2: =Tabela3[[#This Row],[REGISTRO NO SEI/2024]] -> 0 | W2: =Tabela3[[#This Row],[2024]] -> 0 | X2: =Tabela3[[#This Row],[REGISTRO NO SEI/2025]] -> 0 | Y2: =Tabela3[[#This Row],[TOTAL CERTIFICADOS EMITIDOS/2025]] -> 0 | Z2: =Tabela3[[#This Row],[1º trim/2025]] -> 0 | AA2: =Tabela3[[#This Row],[2º trim/2025]] -> 0 | AB2: =Tabela3[[#This Row],[3º trim/2025]] -> 0 | AC2: =Tabela3[[#This Row],[4º trim/2025]] -> 0
